Workbook
Name \0: #REF!
Name \0: #REF!
Name \a: #REF!
Name \a: #REF!
Name \b: #REF!
Name \b: #REF!
Name \d: #REF!
Name \d: #REF!
Name \f: #REF!
Name \f: #REF!
Name \g: #REF!
Name \g: #REF!
Name \h: #REF!
Name \h: #REF!
Name \i: #REF!
Name \i: #REF!
Name \j: #REF!
Name \j: #REF!
Name \k: #REF!
Name \k: #REF!
Name \l: #REF!
Name \l: #REF!
Name \LARGE: #REF!
Name \LARGE: #REF!
Name \m: #REF!
Name \m: #REF!
Name \MIDDLE: #REF!
Name \MIDDLE: #REF!
Name \n: #N/A
Name \o: #N/A
Name \p: #REF!
Name \p: #REF!
Name \q: #REF!
Name \q: #REF!
Name \s: #REF!
Name \s: #REF!
Name \SMALL: #REF!
Name \SMALL: #REF!
Name \t: #REF!
Name \t: #REF!
Name \u: #REF!
Name \u: #REF!
Name \w: #REF!
Name \w: #REF!
Name \X: #REF!
Name \X: #REF!
Name \y: #REF!
Name \y: #REF!
Name \z: #N/A
Name _\D: #REF!
Name _\D: #REF!
Name _\X: #REF!
Name _\X: #REF!
Name ___1.2: [1]BOQ!#REF!
Name ___1.2: [1]BOQ!#REF!
Name ___1.3: [1]BOQ!#REF!
Name ___1.3: [1]BOQ!#REF!
Name ___1.4: [1]BOQ!#REF!
Name ___1.4: [1]BOQ!#REF!
Name ___5A.1: [1]BOQ!#REF!

Sheet Application
A1: CONTRACTOR's INTERIM PAYMENT APPLICATION | J1: ENGINEER'S CERTIFICATE NO. 01
A3: Project Name | B3: : REHABILITATION OF THE A-017 ROAD | F3: Statement No | H3: : 03
B4: CORRIDOR PROJECT (SURIYAKANDA - RAKWANA)
B5: SECTION FROM CH. 112+600 KM TO CH. 118+600 KM | F5: Valuation Period Ending | H5: : 31st December 2022
A8: Contract No: | B8: : RDA/MFAP/ICB/OFID-04(A) | F8: Submission Date | H8: : 10th January 2022
A10: Employer | B10: : Road Development Authority | F10: Commencement Date | H10: : 17th October 2022
A12: Engineer | B12: : | F12: Contract Price | H12: : Rs. 1,825,518,210.94
A14: Contractor | B14: : Consulting Engineers & Contractors (Pvt) Ltd. | F14: Minimum Amount of IPC | H14: : Rs. 54,765,546.33
A16: Payment A/C No. | B16: : 004100630000738 | F16: Limit of Retention | H16: : Rs. 91,275,910.55 | J16: =GS!E29*0.05 -> 91275911
J17: 44810 | K17: =J17+28 -> 44838
A20: 1. Amount of Advance Payment paid to the Contractor (Clause 14.2 of PCC ) | H20: 0
A22: 2. Value of Works executed and all other matters payable (Sub Clause 14.3(a) & (f) GCC | H22: =GS!#REF! -> #REF!
A23: and Sub Clause 13.7 -GCC but not including Item 3 and 7 below.
A25: 3. ADD/DEDUCT Contract Price Fluctuation | E25: (Clause 13.8 of PCC) | H25: =GS!#REF! -> #REF!
A27: 4. Value of Works after Contract Price Fluctuation [2+3] | H27: =H22+H25 -> #REF!
A29: 5. DEDUCT Retention Money @ 10% (Sub Clause 14.2(d) PCC[ Limit : 5% of Contract Price]) | H29: =-H27*0.1 -> #REF!
A31: 6. NET Valuation [4-5] | H31: =H27+H29 -> #REF!
A33: 7. ADD 80% of Materials on Site [Sub Clause14.5(c)(1) GCC ] | H33: ='Mat @ Site (2)'!R45 -> 0
A35: 8. Gross Valuation [6+7] | H35: =H31+H33 -> #REF!
M36: 1.0471017e+09
A37: 9. DEDUCT Cumulative Gross Value of Paid previous Interim Certificate 14.3(g)-GCC | H37: =GS!#REF!*0.9 -> #REF!
A39: 10. Gross Amount of this Interim Certificate [8-9] | H39: =H35-H37 -> #REF!
A41: 11. Release of Retention Money [Sub Clause (14.9)] | H41: 0
A43: 12. DEDUCT Recovery of Advance Payment [Sub Clause 14.2(d) PCC] | H43: =-[10]ADP!F92 -> 0
A45: 13. NET AMOUNT of this Interim Certificate after release of | H45: =H39+H41+H43 -> #REF! | J45: 1.1058192e+08
A46: Retention money and recovery of advance payment [10+11-12]
A48: 14. Value Added Tax [15%] | H48: =H45*0.15 -> #REF! | J48: 0
A50: 15. AMOUNT FOR PAYMENT FOR THIS CERTIFICATE [13 + 14] | H50: =H45+H48 -> #REF! | J50: 5.6804387e+08
A52: 16. Previous cumulative recovery of Advance payment | H52: 0 | J52: =H52+H54 -> 0
A54: 17. Recovery of Advance payment from this IPC | H54: =-H43 -> 0
A56: 18. Balance of Advance Payment to be recovered [1-(16+17)] | H56: =ROUND((H20-H52-H54),2) -> 0
A58: Prepared By | H58: Submitted by
A60: J Garusinghe | H60: WA Premarathna
A61: Quantity Surveyor | H61: Project Manager

Sheet GS
A1: :MISCELLANEOUS FOREIGN AIDED PROJECT
A2: REHABILITATION OF THE A-017 ROAD CORRIDOR PROJECT (SURIYAKANDA - RAKWANA)
A3: FUNDED BY OPEC FUND FOR INTERNATIONAL DEVELOPMENT (OFID)
A4: SECTION FROM CH. 112+600 KM TO CH. 118+600 KM
A5: :RDA/MFAP/ICB/OFID-04(A)
A7: SUMMARY SHEET
E8: AMOUNT ( Sri Lanka Rupees)
A9: Bill No. | B9: Description | D9: Allot. % | E9: Contract
A10: 1 | B10: Preliminary and General | D10: =E10/$E$29 -> 0.0775 | E10: ='Bill 1'!$G$38 -> 1.4151914e+08
A11: 2 | B11: Site Clearing | D11: =E11/$E$29 -> 0.0433 | E11: ='Bill 2'!$G$28 -> 79000094
A12: 3 | B12: Earthworks | D12: =E12/$E$29 -> 0.2505 | E12: ='Bill 3'!$G$43 -> 4.5721e+08
A13: 4 | B13: Road Pavement | D13: =E13/$E$29 -> 0.1213 | E13: ='Bill 4'!$G$27 -> 2.2134931e+08
A14: 5 | B14: Drainage | D14: =E14/$E$29 -> 0.0337 | E14: ='Bill 5'!$G$27 -> 61543114
A15: 6 | B15: Culvert, Retaining Structures | D15: =E15/$E$29 -> 0.2227 | E15: ='Bill 6'!$G$409 -> 4.0649447e+08
A16: 7 | B16: Incidental Construction | D16: =E16/$E$29 -> 0.0292 | E16: ='Bill 7'!$G$140 -> 53339166
A17: 8-1 | B17: Day Works - Labour | D17: =E17/$E$29 -> 0.0004 | E17: ='Bill 8.1'!$G$41 -> 805454.7
A18: 8-2 | B18: Day Works - Equipment | D18: =E18/$E$29 -> 0.0007 | E18: ='Bill 8.2'!$G$104 -> 1368785.9
A19: 8-3 | B19: Day Works - Materials | D19: =E19/$E$29 -> 0.001 | E19: ='Bill 8.3'!$G$103 -> 1785035.3
A20: 9 | B20: Provisional Sums | D20: =E20/$E$29 -> 0.0197 | E20: ='Bill 9'!$G$31 -> 36000000
A21: SUB - Total 1 :(Excl. Provisional Sums) | D21: =E21/$E$29 -> 0.7803 | E21: =SUM(E10:E19) -> 1.4244146e+09
A22: SUB - Total 2 :Provisional Sums | D22: =E22/$E$29 -> 0.0197 | E22: =E20 -> 36000000
A23: A | B23: TOTAL BOQ AMOUNT | D23: =SUM(D21:D22) -> 0.8 | E23: =SUM(E21:E22) -> 1.4604146e+09
A24: B | B24: Variation Orders | D24: =E24/$E$29 -> 0 | E24: 0
A25: C | B25: Claims | D25: =E25/$E$29 -> 0 | E25: 0
A26: D | B26: Construction Cost Total (A+B+C) | D26: =E26/$E$29 -> 0.8 | E26: =SUM(E23:E25) -> 1.4604146e+09
A27: E | B27: Physical Contingencies at 10% of SUB (1 + 2) | D27: =E27/$E$29 -> 0.08 | E27: =E23*0.1 -> 1.4604146e+08
A28: F | B28: Financial Contingencies at 15% of SUB (1 + 2) | D28: =E28/$E$29 -> 0.12 | E28: =E23*0.15 -> 2.1906219e+08
A29: SUB - Total 3:Total Project Cost (D+E+F) without VAT | D29: =E29/$E$29 -> 1 | E29: =SUM(E26:E28) -> 1.8255182e+09
A30: Value Added Tax 15% (For the Contract Amount) and 0% (For the Contract Price) of Sub Total 03 | D30: =E30/E29 -> 0.15 | E30: =E29*15% -> 2.7382773e+08
A31: Total Project cost with VAT | D31: =E31/E29 -> 1.15 | E31: =ROUND(SUM(E29:E30),2) -> 2.0993459e+09

Sheet Mat @ Site (2)
A1: REHABILITATION AND IMPROVEMENT TO PERADENIYA-BADULLA-CHENKALADY ROAD FROM PADIYATHALAWA TO THAMPITIYA (219+800 KM - 249+800 KM) OF BADULLA CHENKALADI ROAD IMPROVEMENT PROJECT
G3: CONTRACT PACKAGE: RDA/BCRIP/ICB/SFD/02 | R3: Annex : | T3: E
A4: Employer | D4: : Road Development Authority | O4: Interim Payment Application : | T4: ='[11]BOQ Summary'!G4 -> No. 35
A5: Consultant | D5: : Resources Development Consultants (Pvt) Ltd | O5: Period Ending : | T5: ='[11]BOQ Summary'!G5 -> 31st May 2021
A6: Contractor | D6: : Consulting Engineers & Contractor (Pvt) Ltd | O6: Sub Clause : | T6: 14.5 (c) (i)
A7: Material at Site
A8: S/N | B8: Description | J8: Unit | L8: Quantity | O8: Rate | R8: Amount | S8: Remarks
A9: 1 | B9: Cement (50kg) | J9: Bags | L9: 0 | O9: ='Bill 8.3'!F28 -> 15055.23 | R9: =L9*O9 -> 0
A11: 2 | B11: Bitumen
B12: MC30 | J12: ltr | L12: 0 | R12: =L12*O12 -> 0
B13: Bitumen CRS1 | J13: ltr | L13: 0 | R13: =L13*O13 -> 0
B14: Bitumen CSS1 | J14: ltr | L14: 0 | R14: =L14*O14 -> 0
A15: 3 | B15: Reinforcement Steel
B16: 10 mm (12m) | J16: Tonne | L16: =AD16 -> 0 | R16: =L16*O16 -> 0 | Z16: 1443 | AA16: 0 | AB16: =ROUND((10*10)/162,3) -> 0.617 | AC16: 12 | AD16: =ROUND((AA16*AB16*AC16)/1000,3) -> 0
B17: 12 mm (6m) | J17: Tonne | L17: =AD17 -> 0 | R17: =L17*O17 -> 0 | Z17: 0 | AA17: 0 | AB17: =ROUND((12*12)/162,3) -> 0.889 | AC17: 6 | AD17: =ROUND((AA17*AB17*AC17)/1000,3) -> 0
B18: 12 mm (12m) | J18: Tonne | L18: =AD18 -> 0 | R18: =L18*O18 -> 0 | Z18: 318 | AA18: 0 | AB18: =ROUND((12*12)/162,3) -> 0.889 | AC18: 12 | AD18: =ROUND((AA18*AB18*AC18)/1000,3) -> 0
B19: 16 mm (6m) | J19: Tonne | L19: =AD19 -> 0 | R19: =L19*O19 -> 0 | Z19: 269 | AA19: 0 | AB19: =ROUND((16*16)/162,3) -> 1.58 | AC19: 6 | AD19: =ROUND((AA19*AB19*AC19)/1000,3) -> 0
B20: 16 mm (12m) | J20: Tonne | L20: =AD20 -> 0 | R20: =L20*O20 -> 0 | Z20: 0 | AA20: 0 | AB20: =ROUND((16*16)/162,3) -> 1.58 | AC20: 12 | AD20: =ROUND((AA20*AB20*AC20)/1000,3) -> 0
B21: 20 mm (12m) | J21: Tonne | L21: 0 | R21: =L21*O21 -> 0 | Z21: 0 | AA21: 0 | AB21: =ROUND((20*20)/162,3) -> 2.469 | AC21: 12 | AD21: =ROUND((AA21*AB21*AC21)/1000,3) -> 0
B22: 25 mm (12m) | J22: Tonne | L22: 0 | R22: =L22*O22 -> 0 | Z22: 0 | AA22: 0 | AB22: =ROUND((25*25)/162,3) -> 3.858 | AC22: 12 | AD22: =ROUND((AA22*AB22*AC22)/1000,3) -> 0
B23: 6 mm(Mild Steel) | J23: Tonne | L23: =AD23 -> 0 | R23: =L23*O23 -> 0 | Y23: kg | Z23: 21 | AA23: 0 | AD23: =ROUND((AA23)/1000,3) -> 0
B24: 10 mm(6 m-Mild Steel) | J24: Tonne | L24: =AD24 -> 0 | R24: =L24*O24 -> 0 | Z24: 0 | AA24: 0 | AB24: =ROUND((10*10)/162,3) -> 0.617 | AC24: 6 | AD24: =ROUND((AA24*AB24*AC24)/1000,3) -> 0
B25: 16 mm(6 m-Mild Steel) | J25: Tonne | L25: =AD25 -> 0 | R25: =L25*O25 -> 0 | Z25: 0 | AA25: 0 | AB25: =ROUND((16*16)/162,3) -> 1.58 | AC25: 6 | AD25: =ROUND((AA25*AB25*AC25)/1000,3) -> 0
B26: 20 mm(6 m-Mild Steel) | J26: Tonne | L26: =AD26 -> 0 | R26: =L26*O26 -> 0 | Z26: 0 | AA26: 0 | AB26: =ROUND((20*20)/162,3) -> 2.469 | AC26: 6 | AD26: =ROUND((AA26*AB26*AC26)/1000,3) -> 0
B27: 20 mm(12 m-Mild Steel) | J27: Tonne | L27: =AD27 -> 0 | R27: =L27*O27 -> 0 | Z27: 0 | AA27: 0 | AB27: =ROUND((20*20)/162,3) -> 2.469 | AC27: 12 | AD27: =ROUND((AA27*AB27*AC27)/1000,3) -> 0
B28: 25 mm(6 m-Mild Steel) | J28: Tonne | L28: =AD28 -> 0 | R28: =L28*O28 -> 0 | Z28: 0 | AA28: 0 | AB28: =ROUND((25*25)/162,3) -> 3.858 | AC28: 6 | AD28: =ROUND((AA28*AB28*AC28)/1000,3) -> 0
Z29: 0 | AA29: 0
A30: 4 | B30: Metal (Aggregate 19 mm) | J30: Cu.m | L30: 0 | R30: =L30*O30 -> 0 | AB30: 2.83 | AD30: =ROUND(AA30*AB30,2) -> 0
A32: 5 | B32: Geotextiles | J32: sq.m | L32: 0 | R32: =L32*O32 -> 0
A34: 6 | B34: Aggregates (ABC) | J34: Cu.m | L34: 0 | R34: =L34*O34 -> 0 | W34: =950*2.83/1.42 -> 1893.31 | X34: 4876.13 | Z34: 6297.64 | AA34: =Z34*O34 -> 0 | AD34: =ROUND(AA34+AB34,2) -> 0
W35: 3874.25 | AA35: =AA34-R34 -> 0
A36: 7 | B36: Sand | J36: Cu.m | L36: 0 | R36: =L36*O36 -> 0 | W36: =W34-W35 -> -1980.94 | X36: =W36*O34 -> 0 | AA36: 0 | AB36: 2.83 | AD36: =ROUND(AA36*AB36,2) -> 0
A37: 8 | B37: Precast Units - Bridge Beams
J38: Nos | L38: 0 | R38: =L38*O38 -> 0
A40: 9 | B40: Rubble | J40: Cu.m | L40: =AD40 -> 0 | O40: 0 | R40: =L40*O40 -> 0 | AB40: 2.83 | AD40: =ROUND(AA40*AB40,2) -> 0
A41: 10 | B41: Road Studs & Road Marking Material | J41: Nos | L41: 0 | O41: 0 | R41: =L41*O41 -> 0
A42: 11 | B42: Gabion Boxes | J42: Nos | L42: 0 | O42: 0 | R42: =L42*O42 -> 0
A44: Sub Total | R44: =ROUND(SUM(R9:R42),2) -> 0 | W44: 25455256 | X44: =W44-R44 -> 25455256 | AB44: 21412465 | AC44: =R44-AB44 -> -21412465 | AE44: 3230.6
A45: Total Carried Forward (Sub Total x 80%) | R45: =ROUND(R44*0.8,2) -> 0 | W45: 20364205 | X45: =W45-R45 -> 20364205 | AB45: 17129972 | AC45: =R45-AB45 -> -17129972 | AE45: =AE44*2.83/1.42 -> 6438.45 | AF45: =L34-AE45 -> -6438.45
A46: Note :
...

Sheet Bill 1
A1: CONTRACT NAME | C1: =GS!$A$1 -> :MISCELLANEOUS FOREIGN AIDED PROJECT
C2: =GS!$A$2 -> REHABILITATION OF THE A-017 ROAD CORRIDOR PROJECT (SURIYAKANDA - RAKWANA)
C3: =GS!$A$3 -> FUNDED BY OPEC FUND FOR INTERNATIONAL DEVELOPMENT (OFID)
C4: =GS!$A$4 -> SECTION FROM CH. 112+600 KM TO CH. 118+600 KM
A6: CONTRACT NO | C6: =GS!$A$5 -> :RDA/MFAP/ICB/OFID-04(A)
A9: BILL No.1 : PRELIMINARY AND GENERAL ITEMS
D10: BOQ
A11: Item | C11: Description | D11: Unit | E11: Quantity | F11: Rate | G11: Amount (Rs.)
A12: Bill | B12: Pay
A13: 1.1 | C13: TRAFFIC SAFETY AND CONTROL
A14: 1 | B14: 103(1) | C14: Management, safety & control & Temporary diversion of traffic including provision of a general traffic management plan | D14: mth | E14: 24 | F14: 664201.22 | G14: =E14*F14 -> 15940829 | I14: =F14/30 -> 22140.04
A15: 1.2 | C15: CONTRACTOR'S SITE ESTABLISHMENT
A16: 1 | B16: 108.(1) | C16: Mobilization of contractor's facilities and plant / machinery | D16: LS | E16: 1 | F16: 26568049 | G16: =E16*F16 -> 26568049
A17: 2 | B17: 108.(2) | C17: De-mobilization of contractor's facilities and plant / machinery | D17: LS | E17: 1 | F17: 885601.63 | G17: =E17*F17 -> 885601.63
A18: 1.3 | C18: SETTING OUT, CROSS SECTION SURVEYS AND DRAWINGS
A19: 1 | B19: 117(1) | C19: All necessary surveying, levelling and setting outs including establishment of all control points and monuments | D19: km | E19: 6 | F19: 1328402.4 | G19: =E19*F19 -> 7970414.7
A20: 2 | B20: 117(2) | C20: Preparation of detailed cross sections | D20: nr | E20: 600 | F20: 17712.03 | G20: =E20*F20 -> 10627218
A21: 1.4 | C21: PROJECT SIGN BOARDS
A22: 1 | B22: 118(1) | C22: Provide and maintain project signboards | D22: nr | E22: 2 | F22: 265680.49 | G22: =E22*F22 -> 531360.98
A23: 1.5 | C23: INSURANCE, BONDS AND SECURITIES
A24: 1 | B24: 119.1(1) | C24: Insurance of the works | D24: LS | E24: 1 | F24: 6199211.4 | G24: =E24*F24 -> 6199211.4
A25: 2 | B25: 119.1(2) | C25: Insurance of the contractor's equipment | D25: LS | E25: 1 | F25: 1771203.3 | G25: =E25*F25 -> 1771203.3
A26: 3 | B26: 119.1(3) | C26: Third party insurance | D26: LS | E26: 1 | F26: 885601.63 | G26: =E26*F26 -> 885601.63
A27: 4 | B27: 119.1(4) | C27: Workmen's compensation insurance | D27: LS | E27: 1 | F27: 885601.63 | G27: =E27*F27 -> 885601.63
A28: 5 | B28: 119.2(1) | C28: Performance security | D28: LS | E28: 1 | F28: 2656804.9 | G28: =E28*F28 -> 2656804.9
A29: 6 | B29: 119.2(2) | C29: Bank guarantee for advance payment | D29: LS | E29: 1 | F29: 7084813.1 | G29: =E29*F29 -> 7084813.1
A30: 1.6 | C30: VEHICLES FOR THE EMPLOYER
A31: 1 | B31: 126 (1) | C31: Provide and maintenance of vehicles - Type A | D31: veh-mth | E31: 27 | F31: 442800.82 | G31: =E31*F31 -> 11955622 | I31: =F31/30 -> 14760.03
A32: 1.7 | C32: MAINTENANCE OF EXISTING ROAD
A33: 1 | B33: 121 (1) | C33: Maintenance of road | D33: km-week | E33: 624 | F33: 22140.04 | G33: =E33*F33 -> 13815385 | I33: =(26.57/31)*F33 -> 18976.16
A34: 1.8 | C34: LABORATORY
A35: 1 | B35: 128 (1) | C35: Establishment of Fully furnished Main Laboratory and removal on completion of project. | D35: LS | E35: 1 | F35: 22140041 | G35: =E35*F35 -> 22140041 | I35: =SUM(I14:I33) -> 55876.23
A36: 2 | B36: 128 (3) | C36: Maintain Laboratory and Lab equipment | D36: mth | E36: 27 | F36: 265680.49 | G36: =E36*F36 -> 7173373.2
A37: 3 | B37: 129 (1) | C37: Provide survey equipment for exclusive use of the Employer / Engineer | D37: LS | E37: 1 | F37: 4428010.3 | G37: =E37*F37 -> 4428010.3
A38: Bill No 01. Total Carried to Summary | G38: =SUM(G14:G37) -> 1.4151914e+08

Sheet Bill 2
A1: CONTRACT NAME | C1: ='Bill 1'!C1 -> :MISCELLANEOUS FOREIGN AIDED PROJECT
C2: ='Bill 1'!C2 -> REHABILITATION OF THE A-017 ROAD CORRIDOR PROJECT (SURIYAKANDA - RAKWANA)
C3: ='Bill 1'!C3 -> FUNDED BY OPEC FUND FOR INTERNATIONAL DEVELOPMENT (OFID)
C4: ='Bill 1'!C4 -> SECTION FROM CH. 112+600 KM TO CH. 118+600 KM
A6: CONTRACT NO | C6: ='Bill 1'!C6 -> :RDA/MFAP/ICB/OFID-04(A)
A9: BILL NO 2: SITE CLEARING
D10: BOQ
A11: Item | C11: Description | D11: Unit | E11: Quantity | F11: Rate | G11: Amount (Rs.)
A12: Bill | B12: Pay
A13: 2.1 | C13: CLEARING AND GRUBBING
A14: 1 | B14: 201(1) | C14: Clearing and grubbing | D14: sq.m | E14: 26400 | F14: 265.68 | G14: =E14*F14 -> 7013952
A15: 2 | B15: 201(3) | C15: Removal of trees, girth greater than or equal to 600 and less than 1200 mm | D15: No. | E15: 1080 | F15: 22140.04 | G15: =E15*F15 -> 23911243
A16: 3 | B16: 201(4) | C16: Removal of trees, girth greater than or equal to 1200 and less than 2000 mm | D16: No. | E16: 720 | F16: 30996.07 | G16: =E16*F16 -> 22317170
A17: 4 | B17: 201(5) | C17: Removal of trees, girth greater than 2000 mm. | D17: No. | E17: 480 | F17: 39852.08 | G17: =E17*F17 -> 19128998
A18: 5 | B18: 201(6) | C18: Removal of stumps of previously felled trees;girth 300-600mm | D18: No. | E18: 60 | F18: 13284.02 | G18: =E18*F18 -> 797041.2
A19: 6 | B19: 201(7) | C19: Removal of stumps of previously felled trees;girth 600-1200mm | D19: No. | E19: 54 | F19: 17712.03 | G19: =E19*F19 -> 956449.62
A20: 7 | B20: 201(8) | C20: Removal of stumps of previously felled trees;girth 1200-2000mm | D20: No. | E20: 48 | F20: 22140.05 | G20: =E20*F20 -> 1062722.4
A21: 8 | B21: 201(9) | C21: Removal of stumps of previously felled trees;girth over 2000mm | D21: No. | E21: 48 | F21: 30996.07 | G21: =E21*F21 -> 1487811.4
A22: 9 | B22: 201(10) | C22: Removal of over hanging branches of girth exceeding 300mm. | D22: No. | E22: 90 | F22: 7084.81 | G22: =E22*F22 -> 637632.9
A23: 2.2 | C23: REMOVAL OF EXISTING STRUCTURES | G23: =E23*F23 -> 0
A24: 1 | B24: 202(1) | C24: Dismantaling and removal of brick masonery structure | D24: cu.m | E24: 180 | F24: 3099.61 | G24: =E24*F24 -> 557929.8
A25: 2 | B25: 202(2) | C25: Dismantaling and removal of random rubble structure | D25: cu.m | E25: 150 | F25: 3985.21 | G25: =E25*F25 -> 597781.5
A26: 3 | B26: 202(3) | C26: Dismantaling and removal of concrete structure | D26: cu.m | E26: 90 | F26: 4428.01 | G26: =E26*F26 -> 398520.9
A27: 4 | B27: 202(5) | C27: Remove of fencing | D27: Lm | E27: 150 | F27: 885.6 | G27: =E27*F27 -> 132840
A28: Bill No.2 Total Carried to Summary | G28: =SUM(G13:G27) -> 79000094

Sheet Bill 3
A1: CONTRACT NAME | C1: ='Bill 1'!C1 -> :MISCELLANEOUS FOREIGN AIDED PROJECT
C2: ='Bill 1'!C2 -> REHABILITATION OF THE A-017 ROAD CORRIDOR PROJECT (SURIYAKANDA - RAKWANA)
C3: ='Bill 1'!C3 -> FUNDED BY OPEC FUND FOR INTERNATIONAL DEVELOPMENT (OFID)
C4: ='Bill 1'!C4 -> SECTION FROM CH. 112+600 KM TO CH. 118+600 KM
A6: CONTRACT NO | C6: ='Bill 1'!C6 -> :RDA/MFAP/ICB/OFID-04(A)
A9: BILL No 03: EARTH WORKS
D10: BOQ
A11: Item | C11: Description | D11: Unit | E11: Quantity | F11: Rate | G11: Amount (Rs.)
A12: Bill | B12: Pay
A13: 3.1 | C13: ROADWAY EXCAVATION
A14: 1 | B14: 301(1) | C14: Roadway excavation,soil suitable for fill | D14: cu.m | E14: 4968 | F14: 4428.01 | G14: =E14*F14 -> 21998354
A15: 2 | B15: 301(2) | C15: Roadway excavation, soft rock | D15: cu.m | E15: 9936 | F15: 3099.61 | G15: =E15*F15 -> 30797725
A16: 3 | B16: 301(3) | C16: Roadway excavation, hard rock | D16: cu.m | E16: 19872 | F16: 7084.81 | G16: =E16*F16 -> 1.4078934e+08
A17: 4 | B17: 301(5) | C17: Roadway excavation, unsuitable soil | D17: cu.m | E17: 55642 | F17: 2036.88 | G17: =E17*F17 -> 1.1333608e+08
A18: 5 | B18: 301(7) | C18: Roadway Pavement Excavation. | D18: cu.m | E18: 1075 | F18: 2656.8 | G18: =E18*F18 -> 2856060
A19: 6 | B19: 301(8) | C19: Prepare sub grade in cut areas | D19: sq.m | E19: 35789 | F19: 177.12 | G19: =E19*F19 -> 6338947.7
A20: 7 | B20: 301(9) | C20: Roadway excavation,marshy soil | D20: cu.m | E20: 4968 | F20: 1594.08 | G20: =E20*F20 -> 7919389.4
A21: 8 | B21: 301(5a) | C21: Cutting side drain | D21: cu.m | E21: 3840 | F21: 1771.2 | G21: =E21*F21 -> 6801408
A22: 9 | B22: 301(3a) | C22: Roadway excavation, Hard rock blasting prohibited | D22: cu.m | E22: 994 | F22: 26568.05 | G22: =E22*F22 -> 26408642
A23: 10 | B23: 301(4) | C23: Roadway excavation - Boulder | D23: cu.m | E23: 2981 | F23: 5756.41 | G23: =E23*F23 -> 17159858
A24: 3.2 | C24: EXCAVATION AND BACKFILLING OF STRUCTURES | G24: =E24*F24 -> 0
A25: 1 | B25: 302(1) | C25: Excavation for structures,soil suitable for backfill | D25: cu.m | E25: 842 | F25: 2656.8 | G25: =E25*F25 -> 2237025.6
A26: 2 | B26: 302(3) | C26: Excavation for structures,boulders | D26: cu.m | E26: 281 | F26: 3542.41 | G26: =E26*F26 -> 995417.21
A27: 3 | B27: 302(4) | C27: Excavation for structures,hard rock | D27: cu.m | E27: 842 | F27: 7084.81 | G27: =E27*F27 -> 5965410
A28: 4 | B28: 302(5) | C28: Excavation for structures, unsuitable soil | D28: cu.m | E28: 1685 | F28: 2656.8 | G28: =E28*F28 -> 4476708
A29: 5 | B29: 302(9) | C29: Preparation of base for foundation | D29: LS | E29: 1 | F29: 3542777.5 | G29: =E29*F29 -> 3542777.5
A30: 6 | B30: 302(15) | C30: Excavation in unsuitable soil and backfill with approved soil | D30: cu.m | E30: 1685 | F30: 5313.61 | G30: =E30*F30 -> 8953432.8
A31: 7 | B31: 302(8) | C31: Backfill with granular materials | D31: cu.m | E31: 281 | F31: 3542.41 | G31: =E31*F31 -> 995417.21
A32: 3.3 | C32: EMBANKMENT CONSTRUCTION | G32: =E32*F32 -> 0
A33: 1 | B33: 304(A) | C33: Remove and replace weak material with buolders | D33: Cum | E33: 250 | F33: 5313.61 | G33: =E33*F33 -> 1328402.5
A34: 2 | B34: 304(1a) | C34: Embankment construction using type - 11 material from roadway excavation and compacted in position. | D34: cu.m | E34: 2981 | F34: 2214 | G34: =E34*F34 -> 6599934
A35: 3 | B35: 304(1b) | C35: Embankment construction using type - 1 material from roadway excavation and compacted in position. | D35: cu.m | E35: 1987 | F35: 2214 | G35: =E35*F35 -> 4399218
A36: 4 | B36: 304(2a) | C36: Embankment construction using borrow material compacted in position Type- 11 material | D36: cu.m | E36: 8640 | F36: 2302.56 | G36: =E36*F36 -> 19894118
A37: 5 | B37: 304(2b) | C37: Embankment construction using borrow material compacted in position Type- 1 material | D37: cu.m | E37: 7776 | F37: 2302.56 | G37: =E37*F37 -> 17904707
A38: 6 | B38: 304(3) | C38: Trimming leveling and compaction of original ground | D38: sq.m | E38: 8640 | F38: 177.12 | G38: =E38*F38 -> 1530316.8
A39: 7 | B39: 304(4) | C39: Provide and place Geofabric , Filter Fabric | D39: Sq.m. | E39: 432 | F39: 708.48 | G39: =E39*F39 -> 306063.36
A40: 8 | B40: 304(6) | C40: Embanment Construction using Rock fill | D40: cu.m | E40: 500 | F40: 5756.41 | G40: =E40*F40 -> 2878205
A41: 9 | B41: 801(1) | C41: Top soiling | D41: sq.m | E41: 900 | F41: 354.24 | G41: =E41*F41 -> 318816
A42: 10 | B42: 802(1) | C42: Turfing (Assuming Turfing thickness 150mm) | D42: sq.m | E42: 900 | F42: 531.36 | G42: =E42*F42 -> 478224
A43: Bill No.3 Total Carried to Summary | G43: =SUM(G14:G42) -> 4.5721e+08

Sheet Bill 4
A1: CONTRACT NAME | C1: ='Bill 1'!C1 -> :MISCELLANEOUS FOREIGN AIDED PROJECT
C2: ='Bill 1'!C2 -> REHABILITATION OF THE A-017 ROAD CORRIDOR PROJECT (SURIYAKANDA - RAKWANA)
C3: ='Bill 1'!C3 -> FUNDED BY OPEC FUND FOR INTERNATIONAL DEVELOPMENT (OFID)
C4: ='Bill 1'!C4 -> SECTION FROM CH. 112+600 KM TO CH. 118+600 KM
A6: CONTRACT NO | C6: ='Bill 1'!C6 -> :RDA/MFAP/ICB/OFID-04(A)
A9: BILL No 04: ROAD PAVEMENT
D10: BOQ
A11: Item | C11: Description | D11: Unit | E11: Quantity | F11: Rate | G11: Amount (Rs.)
A12: Bill | B12: Pay
A13: 4.1 | C13: SUB BASES, CAPPING LAYERS AND BASES
A14: 1 | B14: 401(1) | C14: Provide and place Sub-base as compacted in position Type I (upper sub base) | D14: cu.m | E14: 5040 | F14: 4428.01 | G14: =E14*F14 -> 22317170
A15: 2 | B15: 405(1) | C15: Dense graded aggregate base (37.5mm) | D15: cu.m | E15: 9990 | F15: 7084.82 | G15: =E15*F15 -> 70777352
A16: 4.2 | C16: RECONSTRUCTION OF EXISTING BASES
A17: 1 | B17: 408(1) | C17: Base correction | D17: cu.m | E17: 576 | F17: 6199.21 | G17: =E17*F17 -> 3570745
A18: 2 | B18: 408(2) | C18: Scarification of existing base | D18: sq.m | E18: 576 | F18: 265.68 | G18: =E18*F18 -> 153031.68
A19: 4.3 | C19: SHOULDER CONSTRUCTION
A20: 1 | B20: 409(1) | C20: Earthen shoulder as compacted in position | D20: cu.m | E20: 2700 | F20: 3985.21 | G20: =E20*F20 -> 10760067
A21: 4.4 | C21: PRIME COAT AND TACK COAT
A22: 1 | B22: 501(5) | C22: Prime coat with bituminous MC30 over DGAB at the rate of 1lt/sqm including application of blotting material | D22: sq.m | E22: 46620 | F22: 221.4 | G22: =E22*F22 -> 10321668
A23: 2 | B23: 502(2) | C23: Bituminous tack coat using CRS 1 at rate of 0.25 - 0.55 ltr per sq.m | D23: sq.m | E23: 46620 | F23: 177.12 | G23: =E23*F23 -> 8257334.4
A24: 4.5 | C24: ASPHALTIC CONCRETE SURFACING
A25: 1 | B25: 506(1) | C25: Asphalt Concrete in Wearing Course | D25: tonnes | E25: 5711 | F25: 16383.62 | G25: =E25*F25 -> 93566854
A26: 2 | B26: 506(3) | C26: Asphalt Concrete in regulating course | D26: tonnes | E26: 100 | F26: 16250.87 | G26: =E26*F26 -> 1625087
A27: Bill No. 4 Carried to Summary | G27: =SUM(G13:G26) -> 2.2134931e+08

Sheet Bill 5
A1: CONTRACT NAME | C1: ='Bill 1'!C1 -> :MISCELLANEOUS FOREIGN AIDED PROJECT
C2: ='Bill 1'!C2 -> REHABILITATION OF THE A-017 ROAD CORRIDOR PROJECT (SURIYAKANDA - RAKWANA)
C3: ='Bill 1'!C3 -> FUNDED BY OPEC FUND FOR INTERNATIONAL DEVELOPMENT (OFID)
C4: ='Bill 1'!C4 -> SECTION FROM CH. 112+600 KM TO CH. 118+600 KM
A6: CONTRACT NO | C6: ='Bill 1'!C6 -> :RDA/MFAP/ICB/OFID-04(A)
A9: BILL No.5 : DRAINAGE
D10: BOQ
A11: Item | C11: Description | D11: Unit | E11: Quantity | F11: Rate | G11: Amount (Rs.)
A12: Bill | B12: Pay
A13: 5.1 | C13: ROAD SIDE AND LEADAWAY DRAINS
A14: 1 | B14: 302(15) | C14: Excavation for built up drains in unclassified soil & backfilling. | D14: cu.m | E14: 2016 | F14: 3099.61 | G14: =E14*F14 -> 6248813.8
A15: 2 | B15: 302(4) | C15: Excavation for leadaway drains, hard rock | D15: cu.m | E15: 100 | F15: 7084.81 | G15: =E15*F15 -> 708481
A16: 3 | B16: 701(2a) | C16: Lining of drains with in situ class A or B 25/20 concrete | D16: cum | E16: 1260 | F16: 23911.25 | G16: =E16*F16 -> 30128175
A17: 4 | B17: 701(2b) | C17: Lining of drains with in situ class C15/20 concrete | D17: cum | E17: 252 | F17: 20811.65 | G17: =E17*F17 -> 5244535.8
A18: 5 | B18: 701(3) | C18: Lining of drains with R.R. masonry | D18: cum | E18: 40 | F18: 13284.01 | G18: =E18*F18 -> 531360.4
A19: 6 | B19: 701(6a) | C19: 100mm thick Precast concrete cover slab including reinforcement & formwork | D19: sq.m | E19: 168 | F19: 4428.01 | G19: =E19*F19 -> 743905.68
A20: 7 | B20: 701(6b) | C20: 125mm thick Precast concrete cover slab including reinforcement & formwork | D20: sq.m | E20: 202 | F20: 5756.41 | G20: =E20*F20 -> 1162794.8
A21: 8 | B21: 701(6c) | C21: 150mm thick Precast concrete cover slab including reinforcement & formwork | D21: sq.m | E21: 336 | F21: 6642.01 | G21: =E21*F21 -> 2231715.4
A22: 9 | B22: 701(7) | C22: Supply and fixing of Galvanized steel Gratings as per the given Drawings | D22: sq.m | E22: 100 | F22: 4428.01 | G22: =E22*F22 -> 442801
A23: 10 | B23: 1001(2a) | C23: Concrete nominal mix 1:3:6 (37.5mm) as screed to the foundation | D23: cum | E23: 72 | F23: 19483.24 | G23: =E23*F23 -> 1402793.3
A24: 11 | B24: 1002(1) | C24: Steel Reinforcement (Tor Steel) | D24: tonne | E24: 10 | F24: 287820.54 | G24: =E24*F24 -> 2878205.4
A25: 12 | B25: 1008(2) | C25: Formwork rough finish | D25: sq.m | E25: 2520 | F25: 1948.32 | G25: =E25*F25 -> 4909766.4
A26: 13 | B26: 1008(1) | C26: Formwork, smooth finish | D26: sq.m | E26: 2520 | F26: 1948.32 | G26: =E26*F26 -> 4909766.4
A27: Bill No. 5 Carried to Summary | G27: =SUM(G13:G26) -> 61543114

Sheet Bill 6
A1: CONTRACT NAME | C1: ='Bill 1'!C1 -> :MISCELLANEOUS FOREIGN AIDED PROJECT
C2: ='Bill 1'!C2 -> REHABILITATION OF THE A-017 ROAD CORRIDOR PROJECT (SURIYAKANDA - RAKWANA)
C3: ='Bill 1'!C3 -> FUNDED BY OPEC FUND FOR INTERNATIONAL DEVELOPMENT (OFID)
C4: ='Bill 1'!C4 -> SECTION FROM CH. 112+600 KM TO CH. 118+600 KM
A6: CONTRACT NO | C6: ='Bill 1'!C6 -> :RDA/MFAP/ICB/OFID-04(A)
A9: BILL No.6 : BRIDGES,CULVERTS & RETAINING STRUCTURES
D10: BOQ
A11: Item | C11: Description | D11: Unit | E11: Quantity | F11: Rate | G11: Amount (Rs.)
A12: Bill | B12: Pay
A13: 6.1 | C13: CULVERTS
A14: 1 | B14: 705(1) | C14: Aggregate backfill | D14: cu.m | E14: 3456 | F14: 5313.61 | G14: =E14*F14 -> 18363836
A15: 2 | B15: 705(2) | C15: Filter medium | D15: cu.m | E15: 1728 | F15: 6199.21 | G15: =E15*F15 -> 10712235
A16: 3 | B16: 705(3) | C16: Impervious layer (Clay puddle) | D16: cu.m | E16: 311 | F16: 3542.41 | G16: =E16*F16 -> 1101689.5
A17: 4 | B17: 706(1) | C17: Weep hole, PVC pipe (Type 600) - 75mm diameter | D17: l.m | E17: 600 | F17: 2214 | G17: =E17*F17 -> 1328400
A18: 5 | B18: 707(1) | C18: Laying & joining of pipes-600 mm diameter | D18: l.m | E18: 150 | F18: 13284.02 | G18: =E18*F18 -> 1992603
A19: 6 | B19: 707(2) | C19: Laying & joining of pipes-900 mm diameter | D19: l.m | E19: 150 | F19: 17712.03 | G19: =E19*F19 -> 2656804.5
A20: 7 | B20: 707(3) | C20: Laying & joining of pipes-1200 mm diameter | D20: l.m | E20: 150 | F20: 22582.84 | G20: =E20*F20 -> 3387426
A21: 8 | B21: 1001(1a) | C21: Concrete: Grade A 25(20) | D21: cu.m | E21: 1080 | F21: 24354.04 | G21: =E21*F21 -> 26302363
A22: 9 | B22: 1001(1b) | C22: Concrete: Grade A 20(20) | D22: cu.m | E22: 100 | F22: 23025.64 | G22: =E22*F22 -> 2302564
A23: 10 | B23: 1001(2) | C23: Concrete: Grade C 15(37.5) | D23: cu.m | E23: 900 | F23: 20811.64 | G23: =E23*F23 -> 18730476
A24: 11 | B24: 1002(1) | C24: Tor steel reinforcement | D24: ton. | E24: 120 | F24: 287820.53 | G24: =E24*F24 -> 34538464
A25: 12 | B25: 1002(1) | C25: Mild steel reinforcement | D25: ton. | E25: 20 | F25: 265680.49 | G25: =E25*F25 -> 5313609.8
... A34: 21 | B34: 302(11) | C34: Dewatering | D34: LS | E34: 1 | F34: 2656804.9 | G34: =E34*F34 -> 2656804.9
A48: Total Carried Forward | G48: =SUM(G14:G47) -> 1.5110219e+08
A64: Total Brought Forward | G64: =G48 -> 1.5110219e+08
A65: 6.2 | C65: RETAINING STRUCTURES
A66: 1 | B66: 705(1) | C66: Aggregate backfill | D66: cu.m | E66: 1400 | F66: 4428.01 | G66: =E66*F66 -> 6199214
A67: 2 | B67: 705(2) | C67: Filter medium | D67: cu.m | E67: 700 | F67: 5313.61 | G67: =E67*F67 -> 3719527
A68: 3 | B68: 705(3) | C68: Impervious layer (Clay puddle) | D68: cu.m | E68: 700 | F68: 3542.41 | G68: =E68*F68 -> 2479687
A69: 4 | B69: 706(1) | C69: Weep hole, PVC pipe (Type 600) - 75mm diameter | D69: l.m | E69: 467 | F69: 2214 | G69: =E69*F69 -> 1033938
A70: 5 | B70: 1001(1a) | C70: Concrete: Grade A 25(20) | D70: cu.m | E70: 2300 | F70: 23911.24 | G70: =E70*F70 -> 54995852
A71: 6 | B71: 1001(2) | C71: Concrete: Grade15(37.5) | D71: cu.m | E71: 380 | F71: 20811.64 | G71: =E71*F71 -> 7908423.2
A72: 7 | B72: 1002(1) | C72: Tor steel reinforcement | D72: ton. | E72: 190 | F72: 287820.53 | G72: =E72*F72 -> 54685901
A73: 8 | B73: 1006(1a) | C73: R R Masonry using cement mortar 1:5 | D73: cu.m | E73: 600 | F73: 13284.02 | G73: =E73*F73 -> 7970412
A74: 9 | B74: 1006(1b) | C74: 300 x 150 rubble paving with 1:3:6(37.5) concrete mortar | D74: cu.m | E74: 100 | F74: 15940.83 | G74: =E74*F74 -> 1594083
A75: 10 | B75: 1006(3) | C75: Plastering, 1:3 cement sand mix, 12.5mm thick | D75: sq.m | E75: 500 | F75: 1771.2 | G75: =E75*F75 -> 885600
A76: 11 | B76: 1008(1) | C76: Formwork smooth finish | D76: sq.m | E76: 6545 | F76: 1948.32 | G76: =E76*F76 -> 12751754
A77: 12 | B77: 1008(2) | C77: Formwork rough finish | D77: sq.m | E77: 5355 | F77: 1948.32 | G77: =E77*F77 -> 10433254
A78: 13 | B78: 1011(1) | C78: 25 mm - 600mm long Steel dowels | D78: nr | E78: 200 | F78: 2656.8 | G78: =E78*F78 -> 531360
C79: GABION WALLS
...

Sheet Bill 7
A1: CONTRACT NAME | C1: ='Bill 1'!C1 -> :MISCELLANEOUS FOREIGN AIDED PROJECT
C2: ='Bill 1'!C2 -> REHABILITATION OF THE A-017 ROAD CORRIDOR PROJECT (SURIYAKANDA - RAKWANA)
C3: ='Bill 1'!C3 -> FUNDED BY OPEC FUND FOR INTERNATIONAL DEVELOPMENT (OFID)
C4: ='Bill 1'!C4 -> SECTION FROM CH. 112+600 KM TO CH. 118+600 KM
A6: CONTRACT NO | C6: ='Bill 1'!C6 -> :RDA/MFAP/ICB/OFID-04(A)
A9: BILL No.7 : INCIDENTAL CONSTRUCTION
D10: BOQ
A11: Item | C11: Description | D11: Unit | E11: Quantity | F11: Rate | G11: Amount (Rs.)
A12: Bill | B12: Pay
A13: 7.1 | C13: PAVED SIDE WALKS AND PRECAST CONCRETE KERBS
A14: 1 | B14: 806(a) | C14: Supplying and paving of concrete paving blocks including preparation of Base layer and spreading and compaction of 50mm thick bed course material | D14: sq.m | E14: 900 | F14: 3542.41 | G14: =E14*F14 -> 3188169
A15: 2 | B15: 807(1) | C15: Standard kerb | D15: l.m | E15: 540 | F15: 2036.88 | G15: =E15*F15 -> 1099915.2
A16: 3 | B16: 807(2) | C16: Flat/Edge kerb | D16: l.m | E16: 50 | F16: 2036.88 | G16: =E16*F16 -> 101844
A17: 4 | B17: 807(3) | C17: Drop kerb | D17: l.m | E17: 50 | F17: 2036.88 | G17: =E17*F17 -> 101844
A18: 7.2 | C18: GUARD RAILS AND GUARD STONES
A19: 1 | B19: 808(5) | C19: Guard stones | D19: No | E19: 150 | F19: 6199.21 | G19: =E19*F19 -> 929881.5
A20: 2 | B20: 808(1) | C20: Guard rails (W - beam, galvanized steel) | D20: l.m | E20: 150 | F20: 23911.24 | G20: =E20*F20 -> 3586686
A21: 3 | B21: 809(3) a | C21: Supply and fixing of Pedestrian hand rails as per Drawing (S Type) | D21: m | E21: 15 | F21: 19483.24 | G21: =E21*F21 -> 292248.6
A22: 4 | B22: 809(3) b | C22: Supply and fixing of Pedestrian hand rails as per Drawing (P Type) | D22: m | E22: 15 | F22: 19483.24 | G22: =E22*F22 -> 292248.6
A23: 7.3 | C23: ROAD MARKINGS
A24: 1 | B24: 810(1a) | C24: Center line : Continuous | D24: sq.m | E24: 252 | F24: 2656.8 | G24: =E24*F24 -> 669513.6
A25: 2 | B25: 810(1b) | C25: Center line : Intermittent | D25: sq.m | E25: 378 | F25: 2656.8 | G25: =E25*F25 -> 1004270.4
A26: 3 | B26: 810(1c) | C26: Edge line : Continuous | D26: sq.m | E26: 1260 | F26: 2656.8 | G26: =E26*F26 -> 3347568
A27: 4 | B27: 810(1d) | C27: Pedestrian crossing | D27: sq.m | E27: 150 | F27: 2833.93 | G27: =E27*F27 -> 425089.5
A28: 5 | B28: 810(3) | C28: Reflecting road studs | D28: nr | E28: 126 | F28: 2656.8 | G28: =E28*F28 -> 334756.8
A29: 7.4 | C29: TRAFFIC SIGNS
A30: 1 | B30: 811(1) | C30: Single pole, sign area up to 0.5m2 | D30: nr | E30: 60 | F30: 17712.03 | G30: =E30*F30 -> 1062721.8
A31: 2 | B31: 811(2a) | C31: Double pole, sign area up to 1.0m2 | D31: nr | E31: 3 | F31: 221400.41 | G31: =E31*F31 -> 664201.23
A32: 3 | B32: 811(2b) | C32: Double pole, sign area up to 2.0m2 | D32: nr | E32: 2 | F32: 265680.49 | G32: =E32*F32 -> 531360.98
A33: 4 | B33: 811(3) | C33: Chevron warning sign | D33: nr | E33: 120 | F33: 17712.03 | G33: =E33*F33 -> 2125443.6
A34: 5 | B34: 811(4) | C34: Single pole, multiple sign area up to 1.0 m2 | D34: nr | E34: 3 | F34: 154980.29 | G34: =E34*F34 -> 464940.87
A35: 7.5 | C35: KERB INLETS
A36: 1 | B36: 817(1) | C36: Provide kerb inlets | D36: nr | E36: 30 | F36: 3099.61 | G36: =E36*F36 -> 92988.3
A47: Total Carried Forward | G47: =SUM(G14:G36) -> 20315692
A63: Total Brought Forward | G63: =G47 -> 20315692
A64: 7.6 | C64: TRENCH EXCAVATION
A65: 1 | B65: 815(1) | C65: Trench excavation and reinstatements for utility installation | D65: lm | E65: 500 | F65: 2656.8 | G65: =E65*F65 -> 1328400
A66: 7.7 | C66: KILOMETRE POST AND BOUNDARY MARKERS | G66: 0
A67: 1 | B67: 819(1a) | C67: Provide, install and paint new kilometre post | D67: No. | E67: 6 | F67: 22140.04 | G67: =E67*F67 -> 132840.24
A68: 2 | B68: 819(1b) | C68: Provide, install and paint new Boundary marker | D68: No. | E68: 450 | F68: 3321.01 | G68: =E68*F68 -> 1494454.5
...

Sheet Bill 8.1
A1: CONTRACT NAME | C1: ='Bill 1'!C1 -> :MISCELLANEOUS FOREIGN AIDED PROJECT
C2: ='Bill 1'!C2 -> REHABILITATION OF THE A-017 ROAD CORRIDOR PROJECT (SURIYAKANDA - RAKWANA)
C3: ='Bill 1'!C3 -> FUNDED BY OPEC FUND FOR INTERNATIONAL DEVELOPMENT (OFID)
C4: ='Bill 1'!C4 -> SECTION FROM CH. 112+600 KM TO CH. 118+600 KM
A6: CONTRACT NO | C6: ='Bill 1'!C6 -> :RDA/MFAP/ICB/OFID-04(A)
A9: BILL No.8 : SCHEDULE OF DAY WORKS RATES
D10: BOQ
A11: Item | C11: Description | D11: Unit | E11: Quantity | F11: Rate | G11: Amount (Rs.)
A12: Bill | B12: Pay
A13: 8.1 | C13: LABOUR DAY WORKS
A14: 1 | C14: Surveyor | D14: hr | E14: 60 | F14: 885.61 | G14: =E14*F14 -> 53136.6
A15: 2 | C15: Survey Assistant (skilled) | D15: hr | E15: 90 | F15: 442.81 | G15: =E15*F15 -> 39852.9
A16: 3 | C16: Laboratory Technician (skilled) | D16: hr | E16: 90 | F16: 442.8 | G16: =E16*F16 -> 39852
A17: 4 | C17: CAD Operator | D17: hr | E17: 90 | F17: 398.52 | G17: =E17*F17 -> 35866.8
A18: 5 | C18: Draughtsman | D18: hr | E18: 60 | F18: 398.52 | G18: =E18*F18 -> 23911.2
A19: 6 | C19: Foreman | D19: hr | E19: 60 | F19: 398.52 | G19: =E19*F19 -> 23911.2
A20: 7 | C20: Operator, Heavy equipment | D20: hr | E20: 120 | F20: 398.52 | G20: =E20*F20 -> 47822.4
A21: 8 | C21: Operator, Light equipment | D21: hr | E21: 120 | F21: 398.52 | G21: =E21*F21 -> 47822.4
A22: 9 | C22: Driver, Heavy duty vehicle | D22: hr | E22: 110 | F22: 332.1 | G22: =E22*F22 -> 36531
A23: 10 | C23: Driver, Light duty vehicle | D23: hr | E23: 110 | F23: 265.68 | G23: =E23*F23 -> 29224.8
A24: 11 | C24: Mechanic | D24: hr | E24: 45 | F24: 398.52 | G24: =E24*F24 -> 17933.4
A25: 12 | C25: Welder | D25: hr | E25: 45 | F25: 398.52 | G25: =E25*F25 -> 17933.4
... A31: 18 | C31: Unskilled workman (labour) | D31: hr | E31: 550 | F31: 354.24 | G31: =E31*F31 -> 194832
A41: Bill No. 8.1 Carried to Summary | G41: =SUM(G14:G38) -> 805454.7

Sheet Bill 8.2
A1: CONTRACT NAME | C1: ='Bill 1'!C1 -> :MISCELLANEOUS FOREIGN AIDED PROJECT
C2: ='Bill 1'!C2 -> REHABILITATION OF THE A-017 ROAD CORRIDOR PROJECT (SURIYAKANDA - RAKWANA)
C3: ='Bill 1'!C3 -> FUNDED BY OPEC FUND FOR INTERNATIONAL DEVELOPMENT (OFID)
C4: ='Bill 1'!C4 -> SECTION FROM CH. 112+600 KM TO CH. 118+600 KM
A6: CONTRACT NO | C6: ='Bill 1'!C6 -> :RDA/MFAP/ICB/OFID-04(A)
A9: BILL No.8 : SCHEDULE OF DAY WORKS RATES
D10: BOQ
A11: Item | C11: Description | D11: Unit | E11: Quantity | F11: Rate | G11: Amount (Rs.)
A12: Bill | B12: Pay
A13: 8.2 | C13: EQUIPMENT DAY WORKS
A14: 1 | C14: Motor car, diesel, above 2,000 cc | D14: km | E14: 500 | F14: 48.71 | G14: =E14*F14 -> 24355
A15: 2 | C15: Double cabin Pickup 4WD, diesel, above 2,000 cc | D15: km | E15: 500 | F15: 66.42 | G15: =E15*F15 -> 33210
A16: 3 | C16: Lorry, 3 to 5 tones | D16: hr | E16: 20 | F16: 885.58 | G16: =E16*F16 -> 17711.6
A17: 4 | C17: Lorry, 5 to 10 tones | D17: hr | E17: 20 | F17: 1107 | G17: =E17*F17 -> 22140
A18: 5 | C18: Low-loader, 20 to 40 tones | D18: hr | E18: 6 | F18: 8856.02 | G18: =E18*F18 -> 53136.12
A19: 6 | C19: Site dumper, over 1.0 m3 | D19: hr | E19: 6 | F19: 1328.4 | G19: =E19*F19 -> 7970.4
A20: 7 | C20: Tipper truck, up to 5 tones | D20: hr | E20: 6 | F20: 885.6 | G20: =E20*F20 -> 5313.6
A21: 8 | C21: Tipper truck, 5 to 10 tones | D21: hr | E21: 6 | F21: 1106.99 | G21: =E21*F21 -> 6641.94
A22: 9 | C22: Tipper truck, 10 to 15 tones | D22: hr | E22: 8 | F22: 1594.07 | G22: =E22*F22 -> 12752.56
A23: 10 | C23: Bowser, water, up to 6,000 liters with Spray Bar | D23: hr | E23: 10 | F23: 1549.79 | G23: =E23*F23 -> 15497.9
A24: 11 | C24: Bowser, water, 6,000 to 10,000 liters with Spray Bar | D24: hr | E24: 10 | F24: 1948.32 | G24: =E24*F24 -> 19483.2
A25: 12 | C25: Bowser, diesel, up to 6,000 liters | D25: hr | E25: 6 | F25: 2214 | G25: =E25*F25 -> 13284
... A40: 27 | C40: Backhoe, tracked, 100 - 200 HP | D40: hr | E40: 6 | F40: 3542.41 | G40: =E40*F40 -> 21254.46
A50: Total Carried Forward | G50: =SUM(G14:G40) -> 509840.85
A65: Total Brought Forward | G65: =G50 -> 509840.85
A66: 28 | C66: Front-end Loader, Tracked or wheeled, 50 to 100 HP | D66: hr | E66: 6 | F66: 1771.2 | G66: =E66*F66 -> 10627.2
A67: 29 | C67: Front-end Loader, wheeled, 100 to 200 HP | D67: hr | E67: 3 | F67: 2214 | G67: =+E67*F67 -> 6642
A68: 30 | C68: Motor grader, up to 100 HP | D68: hr | E68: 3 | F68: 3365.29 | G68: =+E68*F68 -> 10095.87
A69: 31 | C69: Motor grader, 100 to 150 HP | D69: hr | E69: 6 | F69: 3542.41 | G69: =+E69*F69 -> 21254.46
A70: 32 | C70: Steel-wheeled roller, static, 8 to 12 tones | D70: hr | E70: 6 | F70: 3985.21 | G70: =+E70*F70 -> 23911.26
A71: 33 | C71: Steel-wheeled roller, vibratory, 4 to 8 tones | D71: hr | E71: 6 | F71: 3985.21 | G71: =+E71*F71 -> 23911.26
A72: 34 | C72: Steel-wheeled roller, vibratory, 10 tones | D72: hr | E72: 6 | F72: 4428.01 | G72: =+E72*F72 -> 26568.06
A73: 35 | C73: Pneumatic-tired roller, 8 to 12 tones | D73: hr | E73: 3 | F73: 4428.01 | G73: =+E73*F73 -> 13284.03
A74: 36 | C74: Tandem roller, 6 to 8 tones, Vibrating | D74: hr | E74: 6 | F74: 4428.01 | G74: =+E74*F74 -> 26568.06
A75: 37 | C75: Hand roller, vibratory, 1/2 - 1 tone | D75: hr | E75: 6 | F75: 885.6 | G75: =+E75*F75 -> 5313.6
A76: 38 | C76: Plate compactor, vibratory, over 90 kg | D76: hr | E76: 6 | F76: 708.48 | G76: =+E76*F76 -> 4250.88
A77: 39 | C77: Rammer, mechanical, over 60 kg | D77: hr | E77: 6 | F77: 708.48 | G77: =+E77*F77 -> 4250.88
A78: 40 | C78: Mobile Crane over 15 tones | D78: hr | E78: 3 | F78: 13284.02 | G78: =+E78*F78 -> 39852.06
... A92: 54 | C92: Poker Vibrator, petrol driven | D92: hr | E92: 6 | F92: 354.24 | G92: =+E92*F92 -> 2125.44
A104: Bill No. 8.2 Carried to Summary | G104: =SUM(G65:G92) -> 1368785.9

Sheet Bill 8.3
A1: CONTRACT NAME | C1: ='Bill 1'!C1 -> :MISCELLANEOUS FOREIGN AIDED PROJECT
C2: ='Bill 1'!C2 -> REHABILITATION OF THE A-017 ROAD CORRIDOR PROJECT (SURIYAKANDA - RAKWANA)
C3: ='Bill 1'!C3 -> FUNDED BY OPEC FUND FOR INTERNATIONAL DEVELOPMENT (OFID)
C4: ='Bill 1'!C4 -> SECTION FROM CH. 112+600 KM TO CH. 118+600 KM
A6: CONTRACT NO | C6: ='Bill 1'!C6 -> :RDA/MFAP/ICB/OFID-04(A)
A9: BILL No.8 : SCHEDULE OF DAY WORKS RATES
D10: BOQ
A11: Item | C11: Description | D11: Unit | E11: Quantity | F11: Rate | G11: Amount (Rs.)
A12: Bill | B12: Pay
A13: 8.3 | C13: MATERIAL DAY WORKS
A14: 1 | C14: Aggregate base, dense graded (37.5 mm) | D14: cu.m | E14: 12 | F14: 2036.88 | G14: =E14*F14 -> 24442.56
A15: 2 | C15: Aggregate, 6 mm (crusher fines) | D15: cu.m | E15: 12 | F15: 1948.32 | G15: =E15*F15 -> 23379.84
A16: 3 | C16: Aggregate, 12 mm | D16: cu.m | E16: 12 | F16: 1948.32 | G16: =E16*F16 -> 23379.84
A17: 4 | C17: Aggregate, 20 mm | D17: cu.m | E17: 12 | F17: 1948.32 | G17: =E17*F17 -> 23379.84
A18: 5 | C18: Aggregate, 25 mm | D18: cu.m | E18: 12 | F18: 1948.32 | G18: =E18*F18 -> 23379.84
A19: 6 | C19: Aggregate, 37.5 mm | D19: cu.m | E19: 12 | F19: 1859.76 | G19: =E19*F19 -> 22317.12
A20: 7 | C20: Asphalt concrete, cold mix | D20: mt | E20: 15 | F20: 10627.22 | G20: =E20*F20 -> 159408.3
A21: 8 | C21: Asphalt concrete, hot mix | D21: mt | E21: 15 | F21: 10627.22 | G21: =E21*F21 -> 159408.3
A22: 9 | C22: Bitumen emulsions, ( CRS 1, CRS 2, CSS 1) | D22: ltr | E22: 40 | F22: 97.42 | G22: =E22*F22 -> 3896.8
A23: 10 | C23: Bitumen prime coat, cutback MC 30 | D23: ltr | E23: 40 | F23: 132.84 | G23: =E23*F23 -> 5313.6
A24: 11 | C24: Bitumen, straight run, 60/70 penetration | D24: ltr | E24: 40 | F24: 97.42 | G24: =E24*F24 -> 3896.8
A25: 12 | C25: Bitumen, straight run, 80/100 penetration | D25: ltr | E25: 40 | F25: 97.42 | G25: =E25*F25 -> 3896.8
... A40: 27 | C40: Paint, enamel | D40: ltr | E40: 3 | F40: 1239.84 | G40: =E40*F40 -> 3719.52
A53: Total Carried Forward | G53: =SUM(G14:G40) -> 1091039.3
A65: Total Brought Forward | G65: =G53 -> 1091039.3
A66: 28 | C66: Pipe, PVC, 160 mm diameter (Type 600) | D66: l.m | E66: 15 | F66: 1328.4 | G66: =E66*F66 -> 19926
A67: 29 | C67: Lime | D67: kg | E67: 3 | F67: 88.55 | G67: =+E67*F67 -> 265.65
A68: 30 | C68: Reinforcement, high-yield steel, Grade 460/425 | D68: kg | E68: 250 | F68: 177.12 | G68: =+E68*F68 -> 44280
A69: 31 | C69: Reinforcement, mild steel, Grade 250 | D69: kg | E69: 200 | F69: 177.12 | G69: =+E69*F69 -> 35424
A70: 32 | C70: Rubble, 100 - 150 mm | D70: cu.m | E70: 8 | F70: 1771.2 | G70: =+E70*F70 -> 14169.6
A71: 33 | C71: Rubble, 150 - 225 mm | D71: cu.m | E71: 20 | F71: 1771.2 | G71: =+E71*F71 -> 35424
A72: 34 | C72: River Sand | D72: cu.m | E72: 10 | F72: 13284.02 | G72: =+E72*F72 -> 132840.2
A73: 35 | C73: Reflective, thermoplastic road paint | D73: kg | E73: 10 | F73: 141.71 | G73: =+E73*F73 -> 1417.1
A74: 36 | C74: Timber, Class 2, Sri Lanka Timber Corporation | D74: cu.m | E74: 0.75 | F74: 17712.03 | G74: =+E74*F74 -> 13284.02
A75: 37 | C75: Auto diesel | D75: ltr | E75: 150 | F75: 127.53 | G75: =+E75*F75 -> 19129.5
A76: 38 | C76: Petrol | D76: ltr | E76: 80 | F76: 162.94 | G76: =+E76*F76 -> 13035.2
A77: 39 | C77: kerosene Oil | D77: ltr | E77: 80 | F77: 97.42 | G77: =+E77*F77 -> 7793.6
A78: Materials Sub Total | G78: =SUM(G65:G77) -> 1428028.2
A80: Percentage mark up applicable to materials in Bill No. 8.3 | E80: 0.25 | G80: =G78*E80 -> 357007.05
A103: Bill No. 8.3 Carried to Summary | G103: =G78+G80 -> 1785035.3

Sheet Bill 9
A1: CONTRACT NAME | C1: ='Bill 1'!C1 -> :MISCELLANEOUS FOREIGN AIDED PROJECT
C2: ='Bill 1'!C2 -> REHABILITATION OF THE A-017 ROAD CORRIDOR PROJECT (SURIYAKANDA - RAKWANA)
C3: ='Bill 1'!C3 -> FUNDED BY OPEC FUND FOR INTERNATIONAL DEVELOPMENT (OFID)
C4: ='Bill 1'!C4 -> SECTION FROM CH. 112+600 KM TO CH. 118+600 KM
A6: CONTRACT NO | C6: ='Bill 1'!C6 -> :RDA/MFAP/ICB/OFID-04(A)
A9: BILL No.9 : PROVISIONAL SUMS
D10: BOQ
A11: Item | C11: Description | D11: Unit | E11: Quantity | F11: Rate | G11: Amount (Rs.)
A12: Bill | B12: Pay
A13: 9.1 | C13: HIV AIDS PREVENTION
A14: 1 | B14: 111(1) | C14: Preparation and Implementation of HIV-AIDS Prevention Program | D14: PS | E14: Item | F14: Allow | G14: 100000
A15: 9.2 | C15: SERVICES
A16: 1 | B16: 112(1) | C16: Demolition / Rebuilding of Property | D16: PS | E16: Item | F16: Allow | G16: 1000000
A17: 9.3 | C17: MONITORING, CONTROLLING ENVIRONMENT HAZARDOUS ACTIVITIES AND TAKING REMEDIAL MEASURE
A18: 1 | B18: 120(2) | C18: Construction of Fish Pass, Velocity Breakers, Rain Water Infiltration Holes and Canopy Bridges as given in the Environmental Management and Monitoring Plan | D18: PS | E18: Item | F18: Allow | G18: 3000000
A19: 9.4 | C19: REMOVAL AND REBUILDING EXISTING STRUCTURES
A20: 1 | B20: 202(6a) | C20: Allow for demolishing of culverts, dressed stone structures, fences etc. and removal of obstructions and objectionable materials in preparing right of way and rebuilding of parapet walls, fence, gates or any part of permanent building to the prevailed condition. | D20: PS | E20: Item | F20: Allow | G20: 6000000
A21: 9.5 | C21: UTILITIES RELOCATION
A22: 1 | B22: 203(1) | C22: Diversion, Protection or Removal of Electrical services | D22: PS | E22: Item | F22: Allow | G22: 13000000
A23: 2 | B23: 203(2) | C23: Diversion, Protection or Removal of Water services | D23: PS | E23: Item | F23: Allow | G23: 5000000
A24: 3 | B24: 203(3) | C24: Diversion, Protection or Removal of Telecommunication services | D24: PS | E24: Item | F24: Allow | G24: 5000000
A25: 9.6 | C25: SOIL NAILING AND HORIZONTAL DRAINS AND ROCK BOLTS
A26: 1 | B26: 820.1(1) | C26: Temporary working platform for soil nailing and rock bolts works | D26: PS | E26: Item | F26: Allow | G26: 1000000
A27: 9.7 | C27: MANHOLES, CATCHPITS AND INLETS
A28: 1 | B28: 703(5) | C28: Grade adjustment of existing manholes | D28: PS | E28: Item | F28: Allow | G28: 300000
A29: 9.8 | C29: HOUSING FOR THE EMPLOYER
A30: 1 | B30: 124(3) | C30: Provide Housing, Type 3 | D30: PS | E30: Item | F30: Allow | G30: 1600000
A31: Bill No. 8.1 Carried to Summary | G31: =SUM(G14:G30) -> 36000000

Sheet PF
B1: ='[12]Bill 1'!A1 -> CONTRACT NAME
B2: ='[12]Bill 1'!A2 | C2: ='Bill 1'!C1 -> :MISCELLANEOUS FOREIGN AIDED PROJECT
C3: ='Bill 1'!C2 -> REHABILITATION OF THE A-017 ROAD CORRIDOR PROJECT (SURIYAKANDA - RAKWANA)
C4: ='Bill 1'!C3 -> FUNDED BY OPEC FUND FOR INTERNATIONAL DEVELOPMENT (OFID)
C5: ='Bill 1'!C4 -> SECTION FROM CH. 112+600 KM TO CH. 118+600 KM
B6: ='[12]Bill 1'!A4 -> CONTRACT NO
C7: ='Bill 1'!C6 -> :RDA/MFAP/ICB/OFID-04(A) | I7: Interim Valuation No. | J7: ='Bill 1'!#REF! -> #REF!
I8: Period Ending | J8: ='Bill 1'!#REF! -> #REF!
B9: PRICE FLUCTUATION.
C12: F = 0.966 ( V - Vna ) * E all inputs Px ( Ixc - Ixb )
C13: 100 Ixb
C15: All inputs Where:
C17: F = Price adjustment for the period concerned
C19: V = Current Valuation of workdone for the Period.
C21: V na = Value of non Adjustable element. Or value of work not considered for price variation.
C23: Px = Input percentage of input named X
C25: l xc = Currenet indices of input X
C27: lxb = Base indices of input X
B30: A | C30: Amount Subject to Price Adjustment for the Month of December 2022
C32: No | D32: Description | H32: Amount (SLR) | I32: Amount (SLR)
C33: 1 | D33: Work Done Bill 1 - 9 + Variation Claims | H33: =GS!#REF! -> #REF!
I35: =ROUND(SUM(H33:H34),2) -> #REF! | K35: 5.356168e+08
D36: Less
C37: 1 | D37: Bill 1 - Preliminary & General. | H37: =GS!#REF! -> #REF!
C38: 2 | D38: Provisional Sums (Non Adjustable). | H38: =GS!#REF! -> #REF!
C39: 3 | D39: Extra Work & Variation on the Prices Prevailing | H39: =GS!#REF! -> #REF!
C40: 4 | D40: Day Works | H40: =GS!#REF!+GS!#REF!+GS!#REF! -> #REF!
C41: 5 | D41: Claims | H41: =GS!#REF! -> #REF!
D42: Total Non Adjustable | I42: =SUM(H36:H41) -> #REF! | K42: 4.8476764e+08
C43: Amount Subject to Price Adjustment for the Month of December 2022 | I43: =I35-I42 -> #REF! | K43: 50849153
B57: Prepared By | J57: Submitted by
B59: J Garusinghe | J59: WA Premarathna
B60: Quantity Surveyor | J60: Project Manager
B61: B | C61: Price Adjustment Factor Sub clause( 13.8 PCC & Ap.to.Ten.)
C63: Ref | D63: Input | F63: Input % Px | H63: Indices | J63: Sum of All Inputs Px(Ixc-Ixb)/Ixb | K63: 2022.8
H64: Base Index (Aug 2021) Ixb | I64: Current Index (Dec 2022) Ixc
K65: 2343.1
C66: M1 | D66: Cement | F66: 2.43 | H66: 696.6 | I66: 1742.4 | J66: =ROUND((F66*(I66-H66)/H66),6) -> 3.64814
C67: M6 | D67: Rubble | F67: 0.44 | H67: 885.9 | I67: =K65 -> 2343.1 | J67: =ROUND((F67*(I67-H67)/H67),6) -> 0.723748 | K67: 1036.4
C68: M7 | D68: Metal | F68: 1.67 | H68: 429.9 | I68: =K67 -> 1036.4 | J68: =ROUND((F68*(I68-H68)/H68),6) -> 2.356025
...

Sheet Bill 6 (2)
A1: CONTRACT NAME | C1: ='Bill 1'!C1 -> :MISCELLANEOUS FOREIGN AIDED PROJECT
C2: ='Bill 1'!C2 -> REHABILITATION OF THE A-017 ROAD CORRIDOR PROJECT (SURIYAKANDA - RAKWANA)
C3: ='Bill 1'!C3 -> FUNDED BY OPEC FUND FOR INTERNATIONAL DEVELOPMENT (OFID)
C4: ='Bill 1'!C4 -> SECTION FROM CH. 112+600 KM TO CH. 118+600 KM
A6: CONTRACT NO | C6: ='Bill 1'!C6 -> :RDA/MFAP/ICB/OFID-04(A)
A9: BILL No.6 : BRIDGES,CULVERTS & RETAINING STRUCTURES
D10: BOQ
A11: Item | C11: Description | D11: Unit | E11: Quantity | F11: Rate | G11: Amount (Rs.)
A12: Bill | B12: Pay
A13: 6.1 | C13: CULVERTS
A14: 1 | B14: 705(1) | C14: Aggregate backfill | D14: cu.m | E14: 3456 | F14: 5313.61 | G14: =E14*F14 -> 18363836
A15: 2 | B15: 705(2) | C15: Filter medium | D15: cu.m | E15: 1728 | F15: 6199.21 | G15: =E15*F15 -> 10712235
A16: 3 | B16: 705(3) | C16: Impervious layer (Clay puddle) | D16: cu.m | E16: 311 | F16: 3542.41 | G16: =E16*F16 -> 1101689.5
A17: 4 | B17: 706(1) | C17: Weep hole, PVC pipe (Type 600) - 75mm diameter | D17: l.m | E17: 600 | F17: 2214 | G17: =E17*F17 -> 1328400
A18: 5 | B18: 707(1) | C18: Laying & joining of pipes-600 mm diameter | D18: l.m | E18: 150 | F18: 13284.02 | G18: =E18*F18 -> 1992603
A19: 6 | B19: 707(2) | C19: Laying & joining of pipes-900 mm diameter | D19: l.m | E19: 150 | F19: 17712.03 | G19: =E19*F19 -> 2656804.5
A20: 7 | B20: 707(3) | C20: Laying & joining of pipes-1200 mm diameter | D20: l.m | E20: 150 | F20: 22582.84 | G20: =E20*F20 -> 3387426
A21: 8 | B21: 1001(1a) | C21: Concrete: Grade A 25(20) | D21: cu.m | E21: 1080 | F21: 24354.04 | G21: =E21*F21 -> 26302363
A22: 9 | B22: 1001(1b) | C22: Concrete: Grade A 20(20) | D22: cu.m | E22: 100 | F22: 23025.64 | G22: =E22*F22 -> 2302564
A23: 10 | B23: 1001(2) | C23: Concrete: Grade C 15(37.5) | D23: cu.m | E23: 900 | F23: 20811.64 | G23: =E23*F23 -> 18730476
A24: 11 | B24: 1002(1) | C24: Tor steel reinforcement | D24: ton. | E24: 120 | F24: 287820.53 | G24: =E24*F24 -> 34538464
A25: 12 | B25: 1002(1) | C25: Mild steel reinforcement | D25: ton. | E25: 20 | F25: 265680.49 | G25: =E25*F25 -> 5313609.8
... A34: 21 | B34: 302(11) | C34: Dewatering | D34: LS | E34: 1 | F34: 2656804.9 | G34: =E34*F34 -> 2656804.9
A48: Total Carried Forward | G48: =SUM(G14:G47) -> 1.5110219e+08
A64: Total Brought Forward | G64: =G48 -> 1.5110219e+08
A65: 6.2 | C65: RETAINING STRUCTURES
A66: 1 | B66: 705(1) | C66: Aggregate backfill | D66: cu.m | E66: 1400 | F66: 4428.01 | G66: =E66*F66 -> 6199214
A67: 2 | B67: 705(2) | C67: Filter medium | D67: cu.m | E67: 700 | F67: 5313.61 | G67: =E67*F67 -> 3719527
A68: 3 | B68: 705(3) | C68: Impervious layer (Clay puddle) | D68: cu.m | E68: 700 | F68: 3542.41 | G68: =E68*F68 -> 2479687
A69: 4 | B69: 706(1) | C69: Weep hole, PVC pipe (Type 600) - 75mm diameter | D69: l.m | E69: 467 | F69: 2214 | G69: =E69*F69 -> 1033938
A70: 5 | B70: 1001(1a) | C70: Concrete: Grade A 25(20) | D70: cu.m | E70: 2300 | F70: 23911.24 | G70: =E70*F70 -> 54995852
A71: 6 | B71: 1001(2) | C71: Concrete: Grade15(37.5) | D71: cu.m | E71: 380 | F71: 20811.64 | G71: =E71*F71 -> 7908423.2
A72: 7 | B72: 1002(1) | C72: Tor steel reinforcement | D72: ton. | E72: 190 | F72: 287820.53 | G72: =E72*F72 -> 54685901
A73: 8 | B73: 1006(1a) | C73: R R Masonry using cement mortar 1:5 | D73: cu.m | E73: 600 | F73: 13284.02 | G73: =E73*F73 -> 7970412
A74: 9 | B74: 1006(1b) | C74: 300 x 150 rubble paving with 1:3:6(37.5) concrete mortar | D74: cu.m | E74: 100 | F74: 15940.83 | G74: =E74*F74 -> 1594083
A75: 10 | B75: 1006(3) | C75: Plastering, 1:3 cement sand mix, 12.5mm thick | D75: sq.m | E75: 500 | F75: 1771.2 | G75: =E75*F75 -> 885600
A76: 11 | B76: 1008(1) | C76: Formwork smooth finish | D76: sq.m | E76: 6545 | F76: 1948.32 | G76: =E76*F76 -> 12751754
A77: 12 | B77: 1008(2) | C77: Formwork rough finish | D77: sq.m | E77: 5355 | F77: 1948.32 | G77: =E77*F77 -> 10433254
A78: 13 | B78: 1011(1) | C78: 25 mm - 600mm long Steel dowels | D78: nr | E78: 200 | F78: 2656.8 | G78: =E78*F78 -> 531360
C79: GABION WALLS
...
